Workbook
Name Interns: 'DO NOT DELETE'!$A$34:$C$42
Name mapsy: 'DO NOT DELETE'!$A$34:$D$42
Name PROFESSIONAL: 'DO NOT DELETE'!$A$35:$C$41
Name PROFESSIONAls: 'DO NOT DELETE'!$A$35:$C$41
Name RPm: 'DO NOT DELETE'!$A$35:$C$41
Name RPsy: 'DO NOT DELETE'!$A$45:$C$49
Name table: 'DO NOT DELETE'!$A$1:$C$5

Sheet ORIGINAL QUESTIONNAIRE
A1: CHILD ADAPTIVE FUNCTIONING CHECKLIST (INITIAL SCREENING TOOL)
A3: Date / Petsa
A4: Child’s Name / Pangalan ng Bata:
A5: Age / Edad: | C5: Sex (Kasarian):
A6: Respondent / Sumagot: ☐ Parent (Magulang) ☐ Teacher (Guro) ☐ Caregiver (Tagapag-alaga) ☐ Others (Iba pa): ______________
A8: Instruction / Panuto:
A9: Please answer each statement with YES (OO) if the child is able to do the skill independently or age-appropriately.
A10: (Sagutin ng OO kung nagagawa ng bata ang kasanayan nang naaayon sa kanyang edad at may kaunting gabay lamang.)
A12: I. CONCEPTUAL DOMAIN (Konseptwal na Kakayahan)
A13: (Communication, language, academics)
A14: No. | B14: Detailed Behavioral Indicator (English) | C14: Detalyadong Pahayag (Filipino) | D14: YES | E14: NO
A15: 1 | B15: States full name, age, and identifies parents when asked. | C15: Nasasabi ang buong pangalan, edad, at pangalan ng magulang kapag tinanong. | D15: ☐ | E15: ☐
A16: 2 | B16: Follows 2-step instructions (e.g., “Pick up your bag and sit down”) without repeated prompting. | C16: Nakakasunod sa 2 hakbang na utos nang hindi inuulit-ulit. | D16: ☐ | E16: ☐
A17: 3 | B17: Answers WH-questions (who, what, where, why) appropriately in simple conversations. | C17: Nakakasagot nang tama sa sino, ano, saan, bakit sa simpleng usapan. | D17: ☐ | E17: ☐
A18: 4 | B18: Identifies and names common objects and their use (e.g., spoon is for eating). | C18: Nakikilala ang bagay at alam ang gamit nito. | D18: ☐ | E18: ☐
A19: 5 | B19: Recognizes letters, numbers, colors, or shapes appropriate to age level. | C19: Nakikilala ang letra, numero, kulay o hugis ayon sa edad. | D19: ☐ | E19: ☐
A20: 6 | B20: Can count objects correctly and perform simple math (if age-appropriate). | C20: Nakakabilang ng tama at nakakagawa ng simpleng matematika ayon sa edad. | D20: ☐ | E20: ☐
A21: 7 | B21: Understands time concepts (today, yesterday, tomorrow) and daily schedule. | C21: Naiintindihan ang kahapon, ngayon, bukas at iskedyul ng araw. | D21: ☐ | E21: ☐
A22: 8 | B22: Expresses needs, thoughts, and feelings using understandable words or gestures. | C22: Naipapahayag nang malinaw ang pangangailangan o damdamin. | D22: ☐ | E22: ☐
A23: 9 | B23: Maintains attention on structured task for at least 10–15 minutes (age-appropriate). | C23: Nakakapokus sa gawain ng 10–15 minuto ayon sa edad. | D23: ☐ | E23: ☐
A24: 10 | B24: Demonstrates understanding of cause and effect (e.g., “If I run, I might fall”). | C24: Naiintindihan ang sanhi at bunga ng kilos. | D24: ☐ | E24: ☐
A25: 11 | B25: Understands simple problem-solving (e.g., finds alternative if toy is unavailable). | C25: Nakakaisip ng alternatibong solusyon sa simpleng problema. | D25: ☐ | E25: ☐
A26: 12 | B26: Reads simple words or sentences (if school-aged). | C26: Nakakabasa ng simpleng salita o pangungusap ayon sa edad. | D26: ☐ | E26: ☐
A28: II. SOCIAL DOMAIN
A29: (Interpersonal Skills, Emotional Regulation, Social Awareness)
A30: No. | B30: Detailed Behavioral Indicator (English) | C30: Detalyadong Pahayag (Filipino) | D30: YES | E30: NO
A31: 1 | B31: Initiates interaction with peers or adults appropriately. | C31: Kusang nakikipag-ugnayan sa kapwa bata o nakatatanda. | D31: ☐ | E31: ☐
A32: 2 | B32: Maintains appropriate eye contact during conversation. | C32: Nakikipag-eye contact sa pakikipag-usap. | D32: ☐ | E32: ☐
A33: 3 | B33: Responds appropriately when name is called. | C33: Tumutugon agad kapag tinatawag ang pangalan. | D33: ☐ | E33: ☐
A34: 4 | B34: Engages in cooperative play (sharing, turn-taking). | C34: Nakikipaglaro nang may salitan at pagbabahagi. | D34: ☐ | E34: ☐
A35: 5 | B35: Understands personal space and boundaries. | C35: Naiintindihan ang personal space at limitasyon ng iba. | D35: ☐ | E35: ☐
A36: 6 | B36: Expresses emotions appropriately without extreme reactions. | C36: Naipapahayag ang emosyon nang hindi labis o marahas. | D36: ☐ | E36: ☐
A37: 7 | B37: Recovers from frustration within reasonable time (without prolonged meltdown). | C37: Nakakabawi agad matapos mainis o magalit. | D37: ☐ | E37: ☐
A38: 8 | B38: Shows empathy (comforts others who are hurt or sad). | C38: Nakikiramay kapag may nasasaktan o nalulungkot. | D38: ☐ | E38: ☐
A39: 9 | B39: Follows group rules in school/home setting. | C39: Nakakasunod sa patakaran sa bahay o paaralan. | D39: ☐ | E39: ☐
A40: 10 | B40: Adjusts behavior according to situation (formal vs play setting). | C40: Naaangkop ang kilos sa sitwasyon. | D40: ☐ | E40: ☐
A41: 11 | B41: Understands simple social cues (e.g., someone is angry or joking). | C41: Naiintindihan ang simpleng senyales ng emosyon ng iba. | D41: ☐ | E41: ☐
A42: 12 | B42: Avoids aggressive behaviors (hitting, biting, throwing objects). | C42: Hindi madalas nananakit o naghahagis ng gamit. | D42: ☐ | E42: ☐
A43: 13 | B43: Can recognize familiar faces such as family members, teacher, or peers. | C43: Nakakakilala sa mga pamilyar na mukha tulad ng kapamilya, guro o kaibigan. | D43: ☐ | E43: ☐
A45: III. PRACTICAL DOMAIN
...

Sheet Questionnaire
H1: CMPS-2026-02-18-Rev.1 03012026
A3: CHILD ADAPTIVE FUNCTIONING CHECKLIST (INITIAL SCREENING TOOL)
B5: Child's Name: | G5: Date:
B6: (Pangalan ng Bata) | G6: (Petsa)
B8: Age: | G8: Gender:
B9: (Edad) | G9: (Kasarian)
B11: Respondent: | F11: (If Others, please specify):
B12: (Sumagot)
B14: Instruction: | E14: Please answer each statement with YES if the child is able to do the skill independently or age-appropriately.
D15: (Panuto: | E15: Sagutin ng OO kung nagagawa ng bata ang kasanayan nang naaayon sa kanyang edad at may kaunting gabay lamang.)
B17: I. CONCEPTUAL DOMAIN (Konseptwal na kakayahan)
B18: (Communication, languange, academics)
B19: No. | D19: Detailed Behavioral Indicator (Detalyadong Pahayag) | H19: YES | J19: NO | K19: NOT APPLICABLE
B20: 1 | C20: E | D20: States full name, age, and identifies parents when asked. | I20: =IF(H20="ü",1,0) -> 0
C21: T | D21: Nasasabi ang buong pangalan, edad, at pangalan ng magulang kapag tinanong.
B22: 2 | C22: E | D22: Follows 2-step instructions (e.g., “Pick up your bag and sit down”) without repeated prompting. | I22: =IF(H22="ü",1,0) -> 0
C23: T | D23: Nakakasunod sa 2 hakbang na utos nang hindi inuulit-ulit.
B24: 3 | C24: E | D24: Answers WH-questions (who, what, where, why) appropriately in simple conversations. | I24: =IF(H24="ü",1,0) -> 0
C25: T | D25: Nakakasagot nang tama sa sino, ano, saan, bakit sa simpleng usapan.
B26: 4 | C26: E | D26: Identifies and names common objects and their use (e.g., spoon is for eating). | I26: =IF(H26="ü",1,0) -> 0
C27: T | D27: Nakikilala ang bagay at alam ang gamit nito.
B28: 5 | C28: E | D28: Recognizes letters, numbers, colors, or shapes appropriate to age level. | I28: =IF(H28="ü",1,0) -> 0
C29: T | D29: Nakikilala ang letra, numero, kulay o hugis ayon sa edad.
B30: 6 | C30: E | D30: Can count objects correctly and perform simple math (if age-appropriate). | I30: =IF(H30="ü",1,0) -> 0
C31: T | D31: Nakakabilang ng tama at nakakagawa ng simpleng matematika ayon sa edad.
B32: 7 | C32: E | D32: Understands time concepts (today, yesterday, tomorrow) and daily schedule. | I32: =IF(H32="ü",1,0) -> 0
C33: T | D33: Naiintindihan ang kahapon, ngayon, bukas at iskedyul ng araw.
B34: 8 | C34: E | D34: Expresses needs, thoughts, and feelings using understandable words or gestures. | I34: =IF(H34="ü",1,0) -> 0
C35: T | D35: Naipapahayag nang malinaw ang pangangailangan o damdamin.
B36: 9 | C36: E | D36: Maintains attention on structured task for at least 10–15 minutes (age-appropriate). | I36: =IF(H36="ü",1,0) -> 0
C37: T | D37: Nakakapokus sa gawain ng 10–15 minuto ayon sa edad.
B38: 10 | C38: E | D38: Demonstrates understanding of cause and effect (e.g., “If I run, I might fall”). | I38: =IF(H38="ü",1,0) -> 0
C39: T | D39: Naiintindihan ang sanhi at bunga ng kilos.
B40: 11 | C40: E | D40: Understands simple problem-solving (e.g., finds alternative if toy is unavailable). | I40: =IF(H40="ü",1,0) -> 0
C41: T | D41: Nakakaisip ng alternatibong solusyon sa simpleng problema.
B42: 12 | C42: E | D42: Reads simple words or sentences (if school-aged). | I42: =IF(H42="ü",1,0) -> 0
C43: T | D43: Nakakabasa ng simpleng salita o pangungusap ayon sa edad.
B44: NOTE: | D44: Check “Not Applicable” if the question is not yet appropriate for your child’s age. | G44: Generated Date: | J44: =TODAY() -> 46082
K45: Page 1 of 5
H46: CMPS-2026-02-18-Rev.1 03012026
...

Sheet Autoscoring
A1: CHILD ADAPTIVE FUNCTIONING CHECKLIST INTERPRETATION
A3: NAME: | B3: =Questionnaire!E5 -> 0 | K3: DATE: | L3: =Questionnaire!H5 -> 0
A5: AGE: | B5: =Questionnaire!E8 -> 0 | E5: GENDER: | G5: =Questionnaire!H8 -> 0
A7: CONCEPTUAL, SOCIAL, PRACTICAL DOMAINS | J7: MOTOR DOMAINS
A9: I. CONCEPTUAL | D9: II. SOCIAL | G9: III. PRACTICAL | J9: A. GROSS MOTORS | M9: B. FINE MOTORS
A11: 1 | B11: =Questionnaire!I20 -> 0 | D11: 1 | E11: =Questionnaire!I52 -> 0 | G11: 1 | H11: =Questionnaire!I96 -> 0 | J11: 1 | K11: =Questionnaire!I140 -> 0 | M11: 1 | N11: =Questionnaire!I184 -> 0
A12: 2 | B12: =Questionnaire!I22 -> 0 | D12: 2 | E12: =Questionnaire!I54 -> 0 | G12: 2 | H12: =Questionnaire!I98 -> 0 | J12: 2 | K12: =Questionnaire!I142 -> 0 | M12: 2 | N12: =Questionnaire!I186 -> 0
A13: 3 | B13: =Questionnaire!I24 -> 0 | D13: 3 | E13: =Questionnaire!I56 -> 0 | G13: 3 | H13: =Questionnaire!I100 -> 0 | J13: 3 | K13: =Questionnaire!I144 -> 0 | M13: 3 | N13: =Questionnaire!I188 -> 0
A14: 4 | B14: =Questionnaire!I26 -> 0 | D14: 4 | E14: =Questionnaire!I58 -> 0 | G14: 4 | H14: =Questionnaire!I102 -> 0 | J14: 4 | K14: =Questionnaire!I146 -> 0 | M14: 4 | N14: =Questionnaire!I190 -> 0
A15: 5 | B15: =Questionnaire!I28 -> 0 | D15: 5 | E15: =Questionnaire!I60 -> 0 | G15: 5 | H15: =Questionnaire!I104 -> 0 | J15: 5 | K15: =Questionnaire!I148 -> 0 | M15: 5 | N15: =Questionnaire!I192 -> 0
A16: 6 | B16: =Questionnaire!I30 -> 0 | D16: 6 | E16: =Questionnaire!I62 -> 0 | G16: 6 | H16: =Questionnaire!I106 -> 0 | J16: 6 | K16: =Questionnaire!I150 -> 0 | M16: 6 | N16: =Questionnaire!I194 -> 0
A17: 7 | B17: =Questionnaire!I32 -> 0 | D17: 7 | E17: =Questionnaire!I64 -> 0 | G17: 7 | H17: =Questionnaire!I108 -> 0 | J17: 7 | K17: =Questionnaire!I152 -> 0 | M17: 7 | N17: =Questionnaire!I196 -> 0
A18: 8 | B18: =Questionnaire!I34 -> 0 | D18: 8 | E18: =Questionnaire!I66 -> 0 | G18: 8 | H18: =Questionnaire!I110 -> 0 | J18: 8 | K18: =Questionnaire!I154 -> 0 | M18: 8 | N18: =Questionnaire!I198 -> 0
A19: 9 | B19: =Questionnaire!I36 -> 0 | D19: 9 | E19: =Questionnaire!I68 -> 0 | G19: 9 | H19: =Questionnaire!I112 -> 0 | J19: 9 | K19: =Questionnaire!I156 -> 0 | M19: 9 | N19: =Questionnaire!I200 -> 0
A20: 10 | B20: =Questionnaire!I38 -> 0 | D20: 10 | E20: =Questionnaire!I70 -> 0 | G20: 10 | H20: =Questionnaire!I114 -> 0 | J20: 10 | K20: =Questionnaire!I158 -> 0 | M20: 10 | N20: =Questionnaire!I202 -> 0
A21: 11 | B21: =Questionnaire!I40 -> 0 | D21: 11 | E21: =Questionnaire!I72 -> 0 | G21: 11 | H21: =Questionnaire!I116 -> 0
A22: 12 | B22: =Questionnaire!I42 -> 0 | D22: 12 | E22: =Questionnaire!I74 -> 0 | G22: 12 | H22: =Questionnaire!I118 -> 0
D23: 13 | E23: =Questionnaire!I76 -> 0
A25: Score | B25: =SUM(B11:B22) -> 0 | D25: Score | E25: =SUM(E11:E23) -> 0 | G25: Score | H25: =SUM(H11:H22) -> 0 | J25: Score | K25: =SUM(K11:K21) -> 0 | M25: Score | N25: =SUM(N11:N20) -> 0
A27: Verb. Inter. | B27: =IF(B25<=2,"Severe Motor Impairment", IF(B25<=4,"Moderate Coordination Difficulty", IF(B25<=7,"Mild Motor Difficulty", IF(B25>=8,"Age-appropriate Motor Skills")))) -> Severe Motor Impairment | D27: Verb. Inter. | E27: =IF(E25<=2,"Severe Motor Impairment", IF(E25<=4,"Moderate Coordination Difficulty", IF(E25<=7,"Mild Motor Difficulty", IF(E25>=8,"Age-appropriate Motor Skills")))) -> Severe Motor Impairment | G27: Verb. Inter. | H27: =IF(H25<=2,"Severe Motor Impairment", IF(H25<=4,"Moderate Coordination Difficulty", IF(H25<=7,"Mild Motor Difficulty", IF(H25>=8,"Age-appropriate Motor Skills")))) -> Severe Motor Impairment | J27: Verb. Inter. | K27: =IF(K25<=2,"Severe Motor Impairment", IF(K25<=4,"Moderate Coordination Difficulty", IF(K25<=7,"Mild Motor Difficulty", IF(K25>=8,"Age-appropriate Motor Skills")))) -> Severe Motor Impairment | M27: Verb. Inter. | N27: =IF(N25<=2,"Severe Motor Impairment", IF(N25<=4,"Moderate Coordination Difficulty", IF(N25<=7,"Mild Motor Difficulty", IF(N25>=8,"Age-appropriate Motor Skills")))) -> Severe Motor Impairment
A29: Severity | B29: =IF(B27="Severe Motor Impairment","Severe Motor Delay", IF(B27="Moderate Coordination Difficulty","Moderate Motor Delay", IF(B27="Mild Motor Difficulty","Mild Motor Delay", IF(B27="Age-appropriate Motor Skills","No Significant Delay")))) -> Severe Motor Delay | D29: Severity | E29: =IF(E27="Severe Motor Impairment","Severe Motor Delay", IF(E27="Moderate Coordination Difficulty","Moderate Motor Delay", IF(E27="Mild Motor Difficulty","Mild Motor Delay", IF(E27="Age-appropriate Motor Skills","No Significant Delay")))) -> Severe Motor Delay | G29: Severity | H29: =IF(H27="Severe Motor Impairment","Severe Motor Delay", IF(H27="Moderate Coordination Difficulty","Moderate Motor Delay", IF(H27="Mild Motor Difficulty","Mild Motor Delay", IF(H27="Age-appropriate Motor Skills","No Significant Delay")))) -> Severe Motor Delay | J29: Severity | K29: =IF(K27="Severe Motor Impairment","Severe Motor Delay", IF(K27="Moderate Coordination Difficulty","Moderate Motor Delay", IF(K27="Mild Motor Difficulty","Mild Motor Delay", IF(K27="Age-appropriate Motor Skills","No Significant Delay")))) -> Severe Motor Delay | M29: Severity | N29: =IF(N27="Severe Motor Impairment","Severe Motor Delay", IF(N27="Moderate Coordination Difficulty","Moderate Motor Delay", IF(N27="Mild Motor Difficulty","Mild Motor Delay", IF(N27="Age-appropriate Motor Skills","No Significant Delay")))) -> Severe Motor Delay
J31: Recommendation for Gross Motors | M31: Recommendation for Fine Motors
J32: =IF(K29="Severe Motor Delay","Recommend Pediatric or Physical Therapy referral", IF(K29="Moderate Motor Delay","Recommend Pediatric or Physical Therapy referral", "It can be manageable")) -> Recommend Pediatric or Physical Therapy referral | M32: =IF(N29="Severe Motor Delay","Recommend Occupational Therapy evaluation", IF(N29="Moderate Motor Delay","Recommend Occupational Therapy evaluation", "It can be manageable")) -> Recommend Occupational Therapy evaluation
J35: IF COMBINED MOTOR DEFICITS
J36: {=INDEX('DO NOT DELETE'!C2:C10,MATCH(1,(Autoscoring!K29='DO NOT DELETE'!A2:A10)*(Autoscoring!N29='DO NOT DELETE'!B2:B10),0))} -> Consider developmental pediatric assessment.
A39: GLOBAL NUMERICAL METHOD
A41: CONCEPTUAL | D41: =B25 -> 0
A42: SOCIAL | D42: =E25 -> 0
A43: PRACTICAL | D43: =H25 -> 0
A44: MOTOR DOMAIN | D44: =K25+N25 -> 0
A46: MAXIMUM TOTAL | D46: =SUM(D41:D44) -> 0
A48: OVERALL SEVERITY | D48: =IF(D46<=19,"Severe Impairment", IF(D46<=33,"Moderate Impairment", IF(D46<=44,"Mild Impairment", IF(D46>=45,"Within Age Expectation")))) -> Severe Impairment
A55: Administered by: | J55: Checked and Approved by:
J57: CRISTINE LAE C. ERASGA
A58: =VLOOKUP(A57,mapsy,2,0) -> #N/A | J58: =VLOOKUP(J57,RPsy,3,0) -> Clinic Psychologist / Supervisor
A59: =VLOOKUP(A57,mapsy,3,0) -> #N/A | J59: License No.: | L59: =VLOOKUP(J57,RPsy,2,0) -> 0001942
A60: =VLOOKUP(A57,mapsy,4,0) -> #N/A
A63: CMPS-2026-02-18-Rev.1 03012026 | K63: Generated Date: | M63: =TODAY() -> 46082

Sheet DO NOT DELETE
A1: Recommendation for Gross Motors | B1: Recommendation for Fine Motors | C1: If Combined Motor Deficits
A2: Mild Motor Delay | B2: Mild Motor Delay | C2: N/A
A3: Moderate Motor Delay | B3: Moderate Motor Delay | C3: Consider developmental pediatric assessment.
A4: Severe Motor Delay | B4: Severe Motor Delay | C4: Consider developmental pediatric assessment.
A5: Mild Motor Delay | B5: Moderate Motor Delay | C5: Kindly proceed on the specific recommendation for Fine motors.
A6: Mild Motor Delay | B6: Severe Motor Delay | C6: Kindly proceed on the specific recommendation for Fine motors.
A7: Moderate Motor Delay | B7: Mild Motor Delay | C7: Kindly proceed on the specific recommendation for Gross motors.
A8: Moderate Motor Delay | B8: Severe Motor Delay | C8: Consider developmental pediatric assessment.
A9: Severe Motor Delay | B9: Mild Motor Delay | C9: Kindly proceed on the specific recommendation for Gross motors.
A10: Severe Motor Delay | B10: Moderate Motor Delay | C10: Consider developmental pediatric assessment.
A16: PSYCHOMETRICIAN | B16: CHOICES
A17: DR. JINKY C. MALABANAN
A18: ALMIE M. BUCO | B18: ü
A19: CRISTINE LAE C. ERASGA
A20: CHRISTINE ANNE M. VILLAMARZO
A21: JEROME G. DELA CRUZ | B21: Parent
A22: ERIKA MAE R. FAUSTINO | B22: Teacher
A23: LEERA MAE C. GUEVARRA | B23: Caregiver
A24: MARWIN A. GILBERO JR. | B24: Others
A26: PSYCHOLOGIST
A27: DR. JINKY C. MALABANAN
A28: CRISTINE LAE ERASGA
A29: CHRISTINE ANNE VILLAMARZO
A31: Registered Psychometrician
A32: Registered Psychologist
A34: INTERNS
A35: PROFESSIONAL
A36: JEROME G. DELA CRUZ | B36: Clinic Intern | C36: Field Practicum (MPI 108), MA Psychology | D36: Pamantasan ng Cabuyao (University of Cabuyao)
A37: ERIKA MAE R. FAUSTINO | B37: Clinic Intern | C37: Field Practicum (MPI 108), MA Psychology | D37: Pamantasan ng Cabuyao (University of Cabuyao)
A38: MARWIN A. GILBERO JR. | B38: Clinic Intern | C38: Field Practicum (MPI 108), MA Psychology | D38: Pamantasan ng Cabuyao (University of Cabuyao)
A39: LEERA MAE C. GUEVARRA | B39: Clinic Intern | C39: Field Practicum (MPI 108), MA Psychology | D39: Pamantasan ng Cabuyao (University of Cabuyao)
A40: KENRICK JOHN D. HAMMOND | B40: Clinic Intern | C40: Field Practicum (MPI 108), MA Psychology | D40: Pamantasan ng Cabuyao (University of Cabuyao)
A41: MARIEDHANNE LOUISE O. LANCETA | B41: Clinic Intern | C41: Field Practicum (MPI 108), MA Psychology | D41: Pamantasan ng Cabuyao (University of Cabuyao)
A42: KRISTLE ANNE A. MANALO | B42: Clinic Intern | C42: Field Practicum (MPI 108), MA Psychology | D42: Pamantasan ng Cabuyao (University of Cabuyao)
A45: PROFESSIONAL | B45: License # Rpsy
A46: DR. JINKY C. MALABANAN | B46: 0002278 | C46: Registered Psychologist
A47: ALMIE M. BUCO | B47: 0002437 | C47: Registered Psychologist
A48: CRISTINE LAE C. ERASGA | B48: 0001942 | C48: Clinic Psychologist / Supervisor
A49: CHRISTINE ANNE M. VILLAMARZO | B49: 0001858 | C49: Registered Psychologist
